<?xml version="1.0" encoding="utf-8"?>
<!-- =================================================================================== -->
<!-- |    This document was autogenerated by xacro from arm.xacro                      | -->
<!-- |    EDITING THIS FILE BY HAND IS NOT RECOMMENDED                                 | -->
<!-- =================================================================================== -->
<robot name="kuka_kr10r1100sixx" xmlns:xacro="http://wiki.ros.org/xacro">
  <!-- default colors for robots -->
  <link name="world"/>
  <link name="base_link">
    <visual>
      <origin rpy="0 0 0" xyz="0 0 0"/>
      <geometry>
        <mesh filename="package://arm_description/meshes/visual/base_link.stl"/>
      </geometry>
      <material name="">
        <color rgba="0.945098039216 0.941176470588 0.917647058824 1.0"/>
      </material>
    </visual>
    <collision>
      <origin rpy="0 0 0" xyz="0 0 0"/>
      <geometry>
        <mesh filename="package://arm_description/meshes/collision/base_link.stl"/>
      </geometry>
    </collision>
    <inertial>
      <origin rpy="0 0 0" xyz="0 0 0"/>
      <mass value="16.8"/>
      <inertia ixx="0.312" ixy="-0.000195" ixz="0.0809" iyy="0.411" iyz="0.0000657" izz="0.186"/>
    </inertial>
  </link>
  <joint name="world-base_link" type="fixed">
    <origin rpy="0 0 0" xyz="0 0 0"/>
    <parent link="world"/>
    <child link="base_link"/>
  </joint>
  <link name="link_1">
    <visual>
      <origin rpy="0 0 0" xyz="0 0 0"/>
      <geometry>
        <mesh filename="package://arm_description/meshes/visual/link_1.stl"/>
      </geometry>
      <material name="">
        <color rgba="0.945098039216 0.941176470588 0.917647058824 1.0"/>
      </material>
    </visual>
    <collision>
      <origin rpy="0 0 0" xyz="0 0 0"/>
      <geometry>
        <mesh filename="package://arm_description/meshes/collision/link_1.stl"/>
      </geometry>
    </collision>
    <inertial>
      <origin rpy="0 0 0" xyz="0 0 0"/>
      <mass value="10.0"/>
      <inertia ixx="1.24" ixy="-0.000146" ixz="-0.0353" iyy="1.19" iyz="-0.00761" izz="0.0912"/>
    </inertial>
  </link>
  <joint name="q1" type="revolute">
    <origin rpy="0 0 0" xyz="0 0 0.400"/>
    <parent link="base_link"/>
    <child link="link_1"/>
    <axis xyz="0 0 -1"/>
    <limit effort="0" lower="-2.96705972839" upper="2.96705972839" velocity="5.23598775598"/>
  </joint>
  <link name="link_2">
    <visual>
      <origin rpy="0 0 0" xyz="0 0 0"/>
      <geometry>
        <mesh filename="package://arm_description/meshes/visual/link_2.stl"/>
      </geometry>
      <material name="">
        <color rgba="0.945098039216 0.941176470588 0.917647058824 1.0"/>
      </material>
    </visual>
    <collision>
      <origin rpy="0 0 0" xyz="0 0 0"/>
      <geometry>
        <mesh filename="package://arm_description/meshes/collision/link_2.stl"/>
      </geometry>
    </collision>
    <inertial>
      <origin rpy="0 0 0" xyz="0 0 0"/>
      <mass value="16.2"/>
      <inertia ixx="7.81" ixy="0.00140" ixz="-0.176" iyy="7.78" iyz="0.0459" izz="0.0767"/>
    </inertial>
  </link>
  <joint name="q2" type="revolute">
    <origin rpy="0 0 0" xyz="0.025 0 0"/>
    <parent link="link_1"/>
    <child link="link_2"/>
    <axis xyz="0 1 0"/>
    <limit effort="0" lower="-3.31612557879" upper="0.785398163397" velocity="3.92699081699"/>
  </joint>
  <link name="link_3">
    <visual>
      <origin rpy="0 0 0" xyz="0 0 0"/>
      <geometry>
        <mesh filename="package://arm_description/meshes/visual/link_3.stl"/>
      </geometry>
      <material name="">
        <color rgba="0.945098039216 0.941176470588 0.917647058824 1.0"/>
      </material>
    </visual>
    <collision>
      <origin rpy="0 0 0" xyz="0 0 0"/>
      <geometry>
        <mesh filename="package://arm_description/meshes/collision/link_3.stl"/>
      </geometry>
    </collision>
    <inertial>
      <origin rpy="0 0 0" xyz="0 0 0"/>
      <mass value="4.62"/>
      <inertia ixx="4.37" ixy="-0.00000359" ixz="-0.186" iyy="4.38" iyz="-0.000112" izz="0.0236"/>
    </inertial>
  </link>
  <joint name="q3" type="revolute">
    <origin rpy="0 0 0" xyz="0.560 0 0"/>
    <parent link="link_2"/>
    <child link="link_3"/>
    <axis xyz="0 1 0"/>
    <limit effort="0" lower="-2.09439510239" upper="2.72271363311" velocity="3.92699081699"/>
  </joint>
  <link name="link_4">
    <visual>
      <origin rpy="0 0 0" xyz="0 0 0"/>
      <geometry>
        <mesh filename="package://arm_description/meshes/visual/link_4.stl"/>
      </geometry>
      <material name="">
        <color rgba="0.945098039216 0.941176470588 0.917647058824 1.0"/>
      </material>
    </visual>
    <collision>
      <origin rpy="0 0 0" xyz="0 0 0"/>
      <geometry>
        <mesh filename="package://arm_description/meshes/collision/link_4.stl"/>
      </geometry>
    </collision>
    <inertial>
      <origin rpy="0 0 0" xyz="0 0 0"/>
      <mass value="6.47"/>
      <inertia ixx="6.42" ixy="0.00101" ixz="-2.11" iyy="7.18" iyz="0.00229" izz="0.774"/>
    </inertial>
  </link>
  <joint name="q4" type="revolute">
    <origin rpy="0 0 0" xyz="0 0 0.035"/>
    <parent link="link_3"/>
    <child link="link_4"/>
    <axis xyz="-1 0 0"/>
    <limit effort="0" lower="-3.22885911619" upper="3.22885911619" velocity="6.6497044501"/>
  </joint>
  <link name="link_5">
    <visual>
      <origin rpy="0 0 0" xyz="0 0 0"/>
      <geometry>
        <mesh filename="package://arm_description/meshes/visual/link_5.stl"/>
      </geometry>
      <material name="">
        <color rgba="0.945098039216 0.941176470588 0.917647058824 1.0"/>
      </material>
    </visual>
    <collision>
      <origin rpy="0 0 0" xyz="0 0 0"/>
      <geometry>
        <mesh filename="package://arm_description/meshes/collision/link_5.stl"/>
      </geometry>
    </collision>
    <inertial>
      <origin rpy="0 0 0" xyz="0 0 0"/>
      <mass value="0.711"/>
      <inertia ixx="0.704" ixy="-0.000729" ixz="-0.393" iyy="0.924" iyz="-0.00135" izz="0.221"/>
    </inertial>
  </link>
  <joint name="q5" type="revolute">
    <origin rpy="0 0 0" xyz="0.515 0 0"/>
    <parent link="link_4"/>
    <child link="link_5"/>
    <axis xyz="0 1 0"/>
    <limit effort="0" lower="-2.09439510239" upper="2.09439510239" velocity="5.4279739737"/>
  </joint>
  <link name="link_6">
    <visual>
      <origin rpy="0 0 0" xyz="0 0 0"/>
      <geometry>
        <mesh filename="package://arm_description/meshes/visual/link_6.stl"/>
      </geometry>
      <material name="">
        <color rgba="0.945098039216 0.941176470588 0.917647058824 1.0"/>
      </material>
    </visual>
    <collision>
      <origin rpy="0 0 0" xyz="0 0 0"/>
      <geometry>
        <mesh filename="package://arm_description/meshes/collision/link_6.stl"/>
      </geometry>
    </collision>
    <inertial>
      <origin rpy="0 0 0" xyz="0 0 0"/>
      <mass value="0.0225"/>
      <inertia ixx="0.0223" ixy="0.0" ixz="-0.0137" iyy="0.0307" iyz="0.0" izz="0.00844"/>
    </inertial>
  </link>
  <joint name="q6" type="revolute">
    <origin rpy="0 0 0" xyz="0.080 0 0"/>
    <parent link="link_5"/>
    <child link="link_6"/>
    <axis xyz="-1 0 0"/>
    <limit effort="0" lower="-6.10865238198" upper="6.10865238198" velocity="8.58701991981"/>
  </joint>
  <link name="tool"/>
  <joint name="link_6-tool" type="fixed">
    <parent link="link_6"/>
    <child link="tool"/>
    <origin rpy="0 1.57079632679 0" xyz="0 0 0"/>
  </joint>
</robot>

